<?xml version="1.0"?>

<robot xmlns="http://drake.mit.edu"
 xmlns:xsi="http://www.w3.org/2001/XMLSchema-instance"
 xsi:schemaLocation="http://drake.mit.edu ../../doc/drakeURDF.xsd" name="PlanarManipulator">

  <link name="base_link">
    <visual>
      <origin xyz="0 0 0" rpy="0 0 0" />
      <geometry>
        <box size=".2 .2 .2" />
      </geometry>
      <material name="green">
        <color rgba="0 1 0 1" />
      </material>
    </visual>
  </link>

  <link name="upper_arm">
    <inertial>
      <origin xyz="0 0 -.5" rpy="0 0 0" />
      <mass value="1" />
      <inertia ixx="1" ixy="0" ixz="0" iyy="1" iyz="0" izz="1" />
    </inertial>
    <visual>
      <origin xyz="0 0 -.5" rpy="0 0 0" />
      <geometry>
         <cylinder length="1.1" radius=".05" />
      </geometry>
      <material name="red">
	    <color rgba="1 0 0 1" />
      </material>
    </visual>
  </link>

  <link name="lower_arm">
    <inertial>
      <origin xyz="0 0 -0.5" rpy="0 0 0" />
      <mass value="1" />
      <inertia ixx="1" ixy="0" ixz="0" iyy="1" iyz="0" izz="1" />
    </inertial>
    <visual>
      <origin xyz="0 0 -0.5" rpy="0 0 0" />
      <geometry>
         <cylinder length="1.1" radius=".05" />
      </geometry>
      <material name="blue">
	    <color rgba="0 0 1 1" />
      </material>
    </visual>
  </link>

  <link name="hand">
    <inertial>
      <origin xyz="0 0 0" rpy="0 0 0" />
      <mass value="0.5" />
      <inertia ixx="1" ixy="0" ixz="0" iyy="1" iyz="0" izz="1" />
    </inertial>
    <visual>
      <origin xyz="0 0 0" rpy="0 0 0" />
      <geometry>
         <box size="0.5 0 0.1"/>
      </geometry>
      <material name="green">
	    <color rgba="0 1 0 1" />
      </material>
    </visual>
  </link>

  <link name="l_base_finger">
    <inertial>
      <origin xyz="0 0 -0.125" rpy="0 0 0" />
      <mass value="0.1" />
      <inertia ixx="1" ixy="0" ixz="0" iyy="1" iyz="0" izz="1" />
    </inertial>
    <visual>
      <origin xyz="0 0 -0.125" rpy="0 0 0" />
      <geometry>
         <cylinder length="0.35" radius=".05" />
      </geometry>
      <material name="blue">
	    <color rgba="0 0 1 1" />
      </material>
    </visual>
  </link>

  <link name="r_base_finger">
    <inertial>
      <origin xyz="0 0 -0.125" rpy="0 0 0" />
      <mass value="0.1" />
      <inertia ixx="1" ixy="0" ixz="0" iyy="1" iyz="0" izz="1" />
    </inertial>
    <visual>
      <origin xyz="0 0 -0.125" rpy="0 0 0" />
      <geometry>
         <cylinder length="0.35" radius=".05" />
      </geometry>
      <material name="blue">
	    <color rgba="0 0 1 1" />
      </material>
    </visual>    
  </link>

  <link name="l_tip_finger">
    <inertial>
      <origin xyz="0 0 -0.125" rpy="0 0 0" />
      <mass value="0.1" />
      <inertia ixx="1" ixy="0" ixz="0" iyy="1" iyz="0" izz="1" />
    </inertial>
    <visual>
      <origin xyz="0 0 -0.125" rpy="0 0 0" />
      <geometry>
         <cylinder length="0.35" radius=".05" />
      </geometry>
      <material name="red">
	    <color rgba="1 0 0 1" />
      </material>
    </visual>
  </link>

 <link name="r_tip_finger">
    <inertial>
      <origin xyz="0 0 -0.125" rpy="0 0 0" />
      <mass value="0.1" />
      <inertia ixx="1" ixy="0" ixz="0" iyy="1" iyz="0" izz="1" />
    </inertial>
    <visual>
      <origin xyz="0 0 -0.125" rpy="0 0 0" />
      <geometry>
         <cylinder length="0.35" radius=".05" />
      </geometry>
      <material name="red">
	    <color rgba="1 0 0 1" />
      </material>
    </visual>
  </link>
  
  <joint name="shoulder" type="revolute">
    <parent link="base_link" />
    <child link="upper_arm" />
    <origin xyz="0 0 0" />
    <axis xyz="0 1 0" />
    <dynamics damping="0.1" />
    <limit lower="-pi" upper="pi" />
  </joint>

  <joint name="elbow" type="revolute">
    <parent link="upper_arm" />
    <child link="lower_arm" />
    <origin xyz="0 0 -1" />
    <axis xyz="0 1 0" />
    <dynamics damping="0.1" />
    <limit lower="-pi/2" upper="pi/2" />
  </joint>

  <joint name="wrist" type="fixed">
    <parent link="lower_arm" />
    <child link="hand" />
    <origin xyz="0 0 -1.1" />
  </joint>

  <joint name="l_knuckle" type="revolute">
    <parent link="hand" />
    <child link="l_base_finger" />
    <origin xyz="-0.25 0 0" />
    <axis xyz="0 1 0" />
    <dynamics damping="0.1" />
    <limit lower="-pi/3" upper="pi/2" />
  </joint>

  <joint name="r_knuckle" type="revolute">
    <parent link="hand" />
    <child link="r_base_finger" />
    <origin xyz="0.25 0 0" />
    <axis xyz="0 1 0" />
    <dynamics damping="0.1" />
    <limit lower="-pi/2" upper="pi/3" />
  </joint>

  <joint name="l_mid_finger" type="revolute">
    <parent link="l_base_finger" />
    <child link="l_tip_finger" />
    <origin xyz="0 0 -0.25" />
    <axis xyz="0 1 0" />
    <dynamics damping="0.1" />
    <limit lower="-5*pi/6" upper="0" />
  </joint>

  <joint name="r_mid_finger" type="revolute">
    <parent link="r_base_finger" />
    <child link="r_tip_finger" />
    <origin xyz="0 0 -0.25" />
    <axis xyz="0 1 0" />
    <dynamics damping="0.1" />
    <limit lower="0" upper="5*pi/6" />
  </joint>
  
  <transmission type="SimpleTransmission" name="shoulder_trans">
    <actuator name="shoulder_torque" />
    <joint name="shoulder" />
    <mechanicalReduction>1</mechanicalReduction>
  </transmission>

  <transmission type="SimpleTransmission" name="elbow_trans">
    <actuator name="elbow_torque" />
    <joint name="elbow" />
    <mechanicalReduction>1</mechanicalReduction>
  </transmission>

  <transmission type="SimpleTransmission" name="l_knuckle_trans">
    <actuator name="l_knuckle_torque" />
    <joint name="l_knuckle" />
    <mechanicalReduction>1</mechanicalReduction>
  </transmission>

  <transmission type="SimpleTransmission" name="r_knuckle_trans">
    <actuator name="r_knuckle_torque" />
    <joint name="r_knuckle" />
    <mechanicalReduction>1</mechanicalReduction>
  </transmission>

  <transmission type="SimpleTransmission" name="l_mid_finger_trans">
    <actuator name="l_mid_finger_torque" />
    <joint name="l_mid_finger" />
    <mechanicalReduction>1</mechanicalReduction>
  </transmission>

  <transmission type="SimpleTransmission" name="r_mid_finger_trans">
    <actuator name="r_mid_finger_torque" />
    <joint name="r_mid_finger" />
    <mechanicalReduction>1</mechanicalReduction>
  </transmission>
  
  <frame name="l_finger_tip_f" link="l_tip_finger" xyz="0 0 -0.25" rpy="0 0 0" />
  <frame name="r_finger_tip_f" link="r_tip_finger" xyz="0 0 -0.25" rpy="0 0 0" />
</robot>
